<?xml version="1.0"?>
<robot name="simple_3wheel_robot">

  <!-- MATERIAL -->
  <material name="blue"><color rgba="0 0 0.8 1"/></material>
  <material name="black"><color rgba="0 0 0 1"/></material>
  <material name="red"><color rgba="0.8 0 0 1"/></material>

  <!-- BASE -->
  <link name="base_link">
    <inertial>
      <mass value="5.0"/>
      <origin xyz="0 0 0"/>
      <inertia ixx="0.2" iyy="0.2" izz="0.2" ixy="0" ixz="0" iyz="0"/>
    </inertial>
  </link>

  <!-- CHASSIS -->
  <joint name="chassis_joint" type="fixed">
    <parent link="base_link"/>
    <child link="chassis"/>
    <origin xyz="0 0 0.15"/>
  </joint>

  <link name="chassis">
    <visual>
      <geometry><box size="0.4 0.3 0.15"/></geometry>
      <material name="blue"/>
    </visual>
    <collision>
      <geometry><box size="0.4 0.3 0.15"/></geometry>
    </collision>
    <inertial>
      <mass value="3.0"/>
      <inertia ixx="0.1" iyy="0.1" izz="0.1" ixy="0" ixz="0" iyz="0"/>
    </inertial>
  </link>

  <!-- LEFT WHEEL -->
  <joint name="left_wheel_joint" type="continuous">
    <parent link="base_link"/>
    <child link="left_wheel"/>
    <origin xyz="0 0.2 0.1" rpy="1.5708 0 0"/>
    <axis xyz="0 0 -1"/>
    <dynamics damping="0.2" friction="0.2"/>
    <limit effort="10" velocity="10"/>
  </joint>

  <link name="left_wheel">
    <visual>
      <geometry><cylinder radius="0.1" length="0.05"/></geometry>
      <material name="black"/>
    </visual>
    <collision>
      <geometry><cylinder radius="0.1" length="0.05"/></geometry>
    </collision>
    <inertial>
      <mass value="1.0"/>
      <inertia ixx="0.01" iyy="0.01" izz="0.01" ixy="0" ixz="0" iyz="0"/>
    </inertial>
  </link>

  <!-- RIGHT WHEEL -->
  <joint name="right_wheel_joint" type="continuous">
    <parent link="base_link"/>
    <child link="right_wheel"/>
    <origin xyz="0 -0.2 0.1" rpy="1.5708 0 0"/>
    <axis xyz="0 0 -1"/>
    <dynamics damping="0.2" friction="0.2"/>
    <limit effort="10" velocity="10"/>
  </joint>

  <link name="right_wheel">
    <visual>
      <geometry><cylinder radius="0.1" length="0.05"/></geometry>
      <material name="black"/>
    </visual>
    <collision>
      <geometry><cylinder radius="0.1" length="0.05"/></geometry>
    </collision>
    <inertial>
      <mass value="1.0"/>
      <inertia ixx="0.01" iyy="0.01" izz="0.01" ixy="0" ixz="0" iyz="0"/>
    </inertial>
  </link>

  <!-- CASTER -->
  <joint name="caster_joint" type="fixed">
    <parent link="chassis"/>
    <child link="caster"/>
    <origin xyz="0.25 0 -0.1"/>
  </joint>

  <link name="caster">
    <visual>
      <geometry><sphere radius="0.05"/></geometry>
      <material name="black"/>
    </visual>
    <collision>
      <geometry><sphere radius="0.05"/></geometry>
    </collision>
    <inertial>
      <mass value="1"/>
      <inertia ixx="0.001" iyy="0.001" izz="0.001" ixy="0" ixz="0" iyz="0"/>
    </inertial>
  </link>

  <!-- LIDAR -->
  <joint name="laser_joint" type="fixed">
    <parent link="chassis"/>
    <child link="laser"/>
    <origin xyz="0 0 0.2"/>
  </joint>

  <link name="laser">
    <visual>
      <geometry><cylinder radius="0.05" length="0.05"/></geometry>
      <material name="red"/>
    </visual>
    <collision>
      <geometry><cylinder radius="0.05" length="0.05"/></geometry>
    </collision>
    <inertial>
      <mass value="0.2"/>
      <inertia ixx="0.0001" iyy="0.0001" izz="0.0001" ixy="0" ixz="0" iyz="0"/>
    </inertial>
  </link>

  <!-- FRICTION -->
  <gazebo reference="left_wheel">
    <mu1>1.2</mu1>
    <mu2>0.3</mu2>
    <slip1>0.0</slip1>
    <slip2>0.1</slip2>
  </gazebo>

  <gazebo reference="right_wheel">
    <mu1>1.2</mu1>
    <mu2>0.3</mu2>
    <slip1>0.0</slip1>
    <slip2>0.1</slip2>
  </gazebo>

  <gazebo reference="base_link">
    <mu1>1.0</mu1>
    <mu2>1.0</mu2>
  </gazebo>

  <!-- DIFF DRIVE -->
  <gazebo>
    <plugin name="diff_drive" filename="libgazebo_ros_diff_drive.so">
      <left_joint>left_wheel_joint</left_joint>
      <right_joint>right_wheel_joint</right_joint>
      <wheel_separation>0.4</wheel_separation>
      <wheel_diameter>0.2</wheel_diameter>
      <publish_odom>true</publish_odom>
      <publish_odom_tf>true</publish_odom_tf>
      <odometry_frame>odom</odometry_frame>
      <robot_base_frame>base_link</robot_base_frame>
      <ros>
        <remapping>cmd_vel:=/cmd_vel</remapping>
      </ros>
    </plugin>
  </gazebo>

  <!-- LIDAR SENSOR -->
  <gazebo reference="laser">
    <sensor type="ray" name="lidar">
      <update_rate>10</update_rate>
      <ray>
        <scan>
          <horizontal>
            <samples>720</samples>
            <min_angle>-3.14</min_angle>
            <max_angle>3.14</max_angle>
          </horizontal>
        </scan>
        <range>
          <min>0.12</min>
          <max>8.0</max>
          <resolution>0.01</resolution>
        </range>
      </ray>

      <plugin name="laser_plugin" filename="libgazebo_ros_ray_sensor.so">
        <ros>
          <namespace>/</namespace>
          <remapping>~/scan:=/scan</remapping>
        </ros>
        <frame_name>laser</frame_name>
        <topicName>/scan</topicName>
      </plugin>
    </sensor>
  </gazebo>

</robot>